<sdf version='1.6'>
  <model name='summit_xl'>
    <link name='summit_xl_base_footprint'>
      <pose frame=''>0 0 0 0 -0 0</pose>
      <inertial>
        <pose frame=''>0.001614 -5.7e-05 0.128062 0 -0 0</pose>
        <mass>125.566</mass>
        <inertia>
          <ixx>1.42636</ixx>
          <ixy>0.00653222</ixy>
          <ixz>-0.0475425</ixz>
          <iyy>6.95718</iyy>
          <iyz>0.00168084</iyz>
          <izz>6.20139</izz>
        </inertia>
      </inertial>
      <collision name='summit_xl_base_footprint_fixed_joint_lump__summit_xl_collision_box_collision'>
        <pose frame=''>0 0 0.5 0 -0 0</pose>
        <geometry>
          <box>
            <size>0.8 0.8 0.8</size>
          </box>
        </geometry>
      </collision>
      <collision name='summit_xl_base_footprint_fixed_joint_lump__summit_xl_base_link_collision_1'>
        <pose frame=''>0 0 0.127 0 -0 0</pose>
        <geometry>
          <mesh>
            <scale>1 1 1</scale>
            <uri>model://summit_xl_description/meshes/bases/xls/summit_xls_chassis.dae</uri>
          </mesh>
        </geometry>
        <surface>
          <contact>
            <ode/>
          </contact>
          <friction>
            <ode/>
          </friction>
        </surface>
      </collision>
      <collision name='summit_xl_base_footprint_fixed_joint_lump__summit_xl_front_rgbd_camera_link_collision_2'>
        <pose frame=''>0.3585 -0.0125 0.36262 0 -0 0</pose>
        <geometry>
          <mesh>
            <scale>1 1 1</scale>
            <uri>model://robotnik_sensors/meshes/orbbec_astra.dae</uri>
          </mesh>
        </geometry>
      </collision>
      <visual name='summit_xl_base_footprint_visual'>
        <pose frame=''>0 0 0 0 -0 0</pose>
        <geometry>
          <box>
            <size>0.001 0.001 0.001</size>
          </box>
        </geometry>
      </visual>
      <visual name='summit_xl_base_footprint_fixed_joint_lump__summit_xl_base_link_visual_1'>
        <pose frame=''>0 0 0.127 0 -0 0</pose>
        <geometry>
          <mesh>
            <scale>1 1 1</scale>
            <uri>model://summit_xl_description/meshes/bases/xls/summit_xls_chassis.stl</uri>
          </mesh>
        </geometry>
        <material>
          <script>
            <name>Gazebo/Black</name>
            <uri>file://media/materials/scripts/gazebo.material</uri>
          </script>
        </material>
      </visual>
      <visual name='summit_xl_base_footprint_fixed_joint_lump__summit_xl_base_logo_front_visual_2'>
        <pose frame=''>0.345 0 0.127 0 0 -1.5708</pose>
        <geometry>
          <mesh>
            <scale>1 1 1</scale>
            <uri>model://summit_xl_description/meshes/bases/xls/robotnik_logo_chasis.stl</uri>
          </mesh>
        </geometry>
      </visual>
      <visual name='summit_xl_base_footprint_fixed_joint_lump__summit_xl_base_logo_left_visual_3'>
        <pose frame=''>0 0.28931 0.41762 0 -0 0</pose>
        <geometry>
          <mesh>
            <scale>1 1 1</scale>
            <uri>model://summit_xl_description/meshes/bases/xls/robotnik_logo_chasis.stl</uri>
          </mesh>
        </geometry>
      </visual>
      <visual name='summit_xl_base_footprint_fixed_joint_lump__summit_xl_base_logo_rear_visual_4'>
        <pose frame=''>-0.345 0 0.127 0 -0 1.5708</pose>
        <geometry>
          <mesh>
            <scale>1 1 1</scale>
            <uri>model://summit_xl_description/meshes/bases/xls/robotnik_logo_chasis.stl</uri>
          </mesh>
        </geometry>
      </visual>
      <visual name='summit_xl_base_footprint_fixed_joint_lump__summit_xl_base_logo_right_visual_5'>
        <pose frame=''>0 -0.28931 0.41762 0 -0 -3.14159</pose>
        <geometry>
          <mesh>
            <scale>1 1 1</scale>
            <uri>model://summit_xl_description/meshes/bases/xls/robotnik_logo_chasis.stl</uri>
          </mesh>
        </geometry>
      </visual>
      <visual name='summit_xl_base_footprint_fixed_joint_lump__summit_xl_base_chapa_visual_6'>
        <pose frame=''>0 0 0.50762 0 -0 0</pose>
        <geometry>
          <mesh>
            <scale>1 1 1</scale>
            <uri>model://summit_xl_description/meshes/bases/xls/summit_xls_chapas_inox_tapas.stl</uri>
          </mesh>
        </geometry>
      </visual>
      <visual name='summit_xl_base_footprint_fixed_joint_lump__summit_xl_front_rgbd_camera_link_visual_7'>
        <pose frame=''>0.3585 -0.0125 0.36262 0 -0 0</pose>
        <geometry>
          <mesh>
            <scale>1 1 1</scale>
            <uri>model://robotnik_sensors/meshes/orbbec_astra.dae</uri>
          </mesh>
        </geometry>
      </visual>
      <visual name='summit_xl_base_footprint_fixed_joint_lump__summit_xl_imu_link_visual_8'>
        <pose frame=''>0.127 -0.129 0.339 0 -0 0</pose>
        <geometry>
          <box>
            <size>0.001 0.001 0.001</size>
          </box>
        </geometry>
        <material>
          <script>
            <uri>__default__</uri>
            <name>__default__</name>
          </script>
        </material>
      </visual>
      <velocity_decay/>
      <velocity_decay/>
      <sensor name='body_contact' type='contact'>
        <contact>
          <collision>robot::robot_base_footprint::robot_base_footprint_fixed_joint_lump__robot_collision_box_collision</collision>
          <topic>__default_topic__</topic>
        </contact>
        <plugin name='body_plugin' filename='libgazebo_ros_bumper.so'>
          <alwaysOn>1</alwaysOn>
          <bumperTopicName>body_contact</bumperTopicName>
          <frameName>summit_xl_base_footprint</frameName>
        </plugin>
        <pose frame=''>0 0 0.127 0 -0 0</pose>
      </sensor>
      <velocity_decay/>
      <sensor name='summit_xl_front_rgbd_camera_depth_sensor' type='depth'>
        <always_on>1</always_on>
        <update_rate>20</update_rate>
        <camera name='__default__'>
          <horizontal_fov>1.0472</horizontal_fov>
          <image>
            <format>R8G8B8</format>
            <width>640</width>
            <height>480</height>
          </image>
          <clip>
            <near>0.05</near>
            <far>3.5</far>
          </clip>
        </camera>
        <plugin name='summit_xl_front_rgbd_camera_controller' filename='libgazebo_ros_openni_kinect.so'>
          <cameraName>front_rgbd_camera</cameraName>
          <alwaysOn>1</alwaysOn>
          <updateRate>10</updateRate>
          <imageTopicName>rgb/image_raw</imageTopicName>
          <depthImageTopicName>depth/image_raw</depthImageTopicName>
          <pointCloudTopicName>depth/points</pointCloudTopicName>
          <cameraInfoTopicName>rgb/camera_info</cameraInfoTopicName>
          <depthImageCameraInfoTopicName>depth/camera_info</depthImageCameraInfoTopicName>
          <frameName>/summit_xl_front_rgbd_camera_depth_optical_frame</frameName>
          <baseline>0.1</baseline>
          <distortion_k1>0.0</distortion_k1>
          <distortion_k2>0.0</distortion_k2>
          <distortion_k3>0.0</distortion_k3>
          <distortion_t1>0.0</distortion_t1>
          <distortion_t2>0.0</distortion_t2>
          <pointCloudCutoff>0.4</pointCloudCutoff>
        </plugin>
        <pose frame=''>0.3585 0 0.37762 0 -0 0</pose>
      </sensor>
      <gravity>1</gravity>
      <velocity_decay/>
      <gravity>1</gravity>
      <sensor name='summit_xl_imu_imu_sensor' type='imu'>
        <always_on>1</always_on>
        <update_rate>100</update_rate>
        <visualize>1</visualize>
        <topic>__default_topic__</topic>
        <plugin name='summit_xl_imu_imu_plugin' filename='libgazebo_ros_imu_sensor.so'>
          <topicName>imu/data</topicName>
          <bodyName>summit_xl_imu_link</bodyName>
          <updateRateHZ>100.0</updateRateHZ>
          <gaussianNoise>0.0</gaussianNoise>
          <xyzOffset>0 0 0</xyzOffset>
          <rpyOffset>0 0 0</rpyOffset>
          <frameName>summit_xl_imu_link</frameName>
        </plugin>
        <pose frame=''>0.127 -0.129 0.339 0 -0 0</pose>
      </sensor>
    </link>
    <link name='summit_xl_back_left_wheel_link'>
      <pose frame=''>-0.2225 0.2045 0.127 0 -0 0</pose>
      <inertial>
        <pose frame=''>0 0 0 0 -0 0</pose>
        <mass>6.5</mass>
        <inertia>
          <ixx>0.0303095</ixx>
          <ixy>0</ixy>
          <ixz>0</ixz>
          <iyy>0.0524193</iyy>
          <iyz>0</iyz>
          <izz>0.0303095</izz>
        </inertia>
      </inertial>
      <collision name='summit_xl_back_left_wheel_link_collision'>
        <pose frame=''>0 0 0 1.5708 -0 0</pose>
        <geometry>
          <cylinder>
            <length>0.087</length>
            <radius>0.127</radius>
          </cylinder>
        </geometry>
        <surface>
          <contact>
            <ode>
              <kp>1e+07</kp>
              <kd>1</kd>
            </ode>
          </contact>
          <friction>
            <ode>
              <mu>0</mu>
              <mu2>0</mu2>
              <fdir1>1 0 0</fdir1>
            </ode>
          </friction>
        </surface>
      </collision>
      <visual name='summit_xl_back_left_wheel_link_visual'>
        <pose frame=''>0 0 0 0 -0 0</pose>
        <geometry>
          <mesh>
            <scale>1 1 1</scale>
            <uri>model://summit_xl_description/meshes/wheels/omni_wheel_1.dae</uri>
          </mesh>
        </geometry>
        <material>
          <script>
            <uri>__default__</uri>
            <name>__default__</name>
          </script>
        </material>
      </visual>
      <gravity>1</gravity>
      <velocity_decay/>
    </link>
    <joint name='summit_xl_back_left_wheel_joint' type='revolute'>
      <child>summit_xl_back_left_wheel_link</child>
      <parent>summit_xl_base_footprint</parent>
      <axis>
        <xyz>0 1 0</xyz>
        <limit>
          <lower>-1e+16</lower>
          <upper>1e+16</upper>
        </limit>
        <dynamics>
          <spring_reference>0</spring_reference>
          <spring_stiffness>0</spring_stiffness>
        </dynamics>
        <use_parent_model_frame>1</use_parent_model_frame>
      </axis>
    </joint>
    <link name='summit_xl_back_right_wheel_link'>
      <pose frame=''>-0.2225 -0.2045 0.127 0 -0 0</pose>
      <inertial>
        <pose frame=''>0 0 0 0 -0 0</pose>
        <mass>6.5</mass>
        <inertia>
          <ixx>0.0303095</ixx>
          <ixy>0</ixy>
          <ixz>0</ixz>
          <iyy>0.0524193</iyy>
          <iyz>0</iyz>
          <izz>0.0303095</izz>
        </inertia>
      </inertial>
      <collision name='summit_xl_back_right_wheel_link_collision'>
        <pose frame=''>0 0 0 1.5708 -0 0</pose>
        <geometry>
          <cylinder>
            <length>0.087</length>
            <radius>0.127</radius>
          </cylinder>
        </geometry>
        <surface>
          <contact>
            <ode>
              <kp>1e+07</kp>
              <kd>1</kd>
            </ode>
          </contact>
          <friction>
            <ode>
              <mu>0</mu>
              <mu2>0</mu2>
              <fdir1>1 0 0</fdir1>
            </ode>
          </friction>
        </surface>
      </collision>
      <visual name='summit_xl_back_right_wheel_link_visual'>
        <pose frame=''>0 0 0 0 -0 0</pose>
        <geometry>
          <mesh>
            <scale>1 1 1</scale>
            <uri>model://summit_xl_description/meshes/wheels/omni_wheel_2.dae</uri>
          </mesh>
        </geometry>
        <material>
          <script>
            <uri>__default__</uri>
            <name>__default__</name>
          </script>
        </material>
      </visual>
      <gravity>1</gravity>
      <velocity_decay/>
    </link>
    <joint name='summit_xl_back_right_wheel_joint' type='revolute'>
      <child>summit_xl_back_right_wheel_link</child>
      <parent>summit_xl_base_footprint</parent>
      <axis>
        <xyz>0 1 0</xyz>
        <limit>
          <lower>-1e+16</lower>
          <upper>1e+16</upper>
        </limit>
        <dynamics>
          <spring_reference>0</spring_reference>
          <spring_stiffness>0</spring_stiffness>
        </dynamics>
        <use_parent_model_frame>1</use_parent_model_frame>
      </axis>
    </joint>
    <link name='summit_xl_front_laser_base_link'>
      <pose frame=''>0.2865 -0.20894 0.4243 3.14159 0 -0.785398</pose>
      <inertial>
        <pose frame=''>0 0 0 0 -0 0</pose>
        <mass>0.1</mass>
        <inertia>
          <ixx>0.000270833</ixx>
          <ixy>0</ixy>
          <ixz>0</ixz>
          <iyy>0.000270833</iyy>
          <iyz>0</iyz>
          <izz>9.434e-05</izz>
        </inertia>
      </inertial>
      <collision name='summit_xl_front_laser_base_link_collision'>
        <pose frame=''>0 0 0 0 -0 0</pose>
        <geometry>
          <mesh>
            <scale>1 1 1</scale>
            <uri>model://robotnik_sensors/meshes/sick_s300.dae</uri>
          </mesh>
        </geometry>
      </collision>
      <visual name='summit_xl_front_laser_base_link_visual'>
        <pose frame=''>0 0 0 0 -0 0</pose>
        <geometry>
          <mesh>
            <scale>1 1 1</scale>
            <uri>model://robotnik_sensors/meshes/sick_s300.dae</uri>
          </mesh>
        </geometry>
      </visual>
      <gravity>1</gravity>
      <velocity_decay/>
      <sensor name='summit_xl_front_laser_sensor' type='ray'>
        <visualize>0</visualize>
        <update_rate>12.5</update_rate>
        <ray>
          <scan>
            <horizontal>
              <samples>541</samples>
              <resolution>1</resolution>
              <min_angle>-2.3562</min_angle>
              <max_angle>2.3562</max_angle>
            </horizontal>
          </scan>
          <range>
            <min>0.1</min>
            <max>30</max>
            <resolution>0.03</resolution>
          </range>
          <noise>
            <type>gaussian</type>
            <mean>0</mean>
            <stddev>0.03</stddev>
          </noise>
        </ray>
        <plugin name='summit_xl_front_laser_controller' filename='libgazebo_ros_laser.so'>
          <topicName>front_laser/scan</topicName>
          <frameName>/summit_xl_front_laser_link</frameName>
        </plugin>
        <pose frame=''>0 0 0.116 0 -0 0</pose>
      </sensor>
    </link>
    <joint name='summit_xl_front_laser_base_joint' type='revolute'>
      <child>summit_xl_front_laser_base_link</child>
      <parent>summit_xl_base_footprint</parent>
      <axis>
        <xyz>0.707107 -0.707107 -0</xyz>
        <limit>
          <lower>0</lower>
          <upper>0</upper>
          <effort>100</effort>
          <velocity>100</velocity>
        </limit>
        <dynamics>
          <spring_reference>0</spring_reference>
          <spring_stiffness>0</spring_stiffness>
        </dynamics>
        <use_parent_model_frame>1</use_parent_model_frame>
      </axis>
    </joint>
    <link name='summit_xl_front_left_wheel_link'>
      <pose frame=''>0.2225 0.2045 0.127 0 -0 0</pose>
      <inertial>
        <pose frame=''>0 0 0 0 -0 0</pose>
        <mass>6.5</mass>
        <inertia>
          <ixx>0.0303095</ixx>
          <ixy>0</ixy>
          <ixz>0</ixz>
          <iyy>0.0524193</iyy>
          <iyz>0</iyz>
          <izz>0.0303095</izz>
        </inertia>
      </inertial>
      <collision name='summit_xl_front_left_wheel_link_collision'>
        <pose frame=''>0 0 0 1.5708 -0 0</pose>
        <geometry>
          <cylinder>
            <length>0.087</length>
            <radius>0.127</radius>
          </cylinder>
        </geometry>
        <surface>
          <contact>
            <ode>
              <kp>1e+07</kp>
              <kd>1</kd>
            </ode>
          </contact>
          <friction>
            <ode>
              <mu>0</mu>
              <mu2>0</mu2>
              <fdir1>1 0 0</fdir1>
            </ode>
          </friction>
        </surface>
      </collision>
      <visual name='summit_xl_front_left_wheel_link_visual'>
        <pose frame=''>0 0 0 0 -0 0</pose>
        <geometry>
          <mesh>
            <scale>1 1 1</scale>
            <uri>model://summit_xl_description/meshes/wheels/omni_wheel_1.dae</uri>
          </mesh>
        </geometry>
        <material>
          <script>
            <uri>__default__</uri>
            <name>__default__</name>
          </script>
        </material>
      </visual>
      <gravity>1</gravity>
      <velocity_decay/>
    </link>
    <joint name='summit_xl_front_left_wheel_joint' type='revolute'>
      <child>summit_xl_front_left_wheel_link</child>
      <parent>summit_xl_base_footprint</parent>
      <axis>
        <xyz>0 1 0</xyz>
        <limit>
          <lower>-1e+16</lower>
          <upper>1e+16</upper>
        </limit>
        <dynamics>
          <spring_reference>0</spring_reference>
          <spring_stiffness>0</spring_stiffness>
        </dynamics>
        <use_parent_model_frame>1</use_parent_model_frame>
      </axis>
    </joint>
    <link name='summit_xl_front_right_wheel_link'>
      <pose frame=''>0.2225 -0.2045 0.127 0 -0 0</pose>
      <inertial>
        <pose frame=''>0 0 0 0 -0 0</pose>
        <mass>6.5</mass>
        <inertia>
          <ixx>0.0303095</ixx>
          <ixy>0</ixy>
          <ixz>0</ixz>
          <iyy>0.0524193</iyy>
          <iyz>0</iyz>
          <izz>0.0303095</izz>
        </inertia>
      </inertial>
      <collision name='summit_xl_front_right_wheel_link_collision'>
        <pose frame=''>0 0 0 1.5708 -0 0</pose>
        <geometry>
          <cylinder>
            <length>0.087</length>
            <radius>0.127</radius>
          </cylinder>
        </geometry>
        <surface>
          <contact>
            <ode>
              <kp>1e+07</kp>
              <kd>1</kd>
            </ode>
          </contact>
          <friction>
            <ode>
              <mu>0</mu>
              <mu2>0</mu2>
              <fdir1>1 0 0</fdir1>
            </ode>
          </friction>
        </surface>
      </collision>
      <visual name='summit_xl_front_right_wheel_link_visual'>
        <pose frame=''>0 0 0 0 -0 0</pose>
        <geometry>
          <mesh>
            <scale>1 1 1</scale>
            <uri>model://summit_xl_description/meshes/wheels/omni_wheel_2.dae</uri>
          </mesh>
        </geometry>
        <material>
          <script>
            <uri>__default__</uri>
            <name>__default__</name>
          </script>
        </material>
      </visual>
      <gravity>1</gravity>
      <velocity_decay/>
    </link>
    <joint name='summit_xl_front_right_wheel_joint' type='revolute'>
      <child>summit_xl_front_right_wheel_link</child>
      <parent>summit_xl_base_footprint</parent>
      <axis>
        <xyz>0 1 0</xyz>
        <limit>
          <lower>-1e+16</lower>
          <upper>1e+16</upper>
        </limit>
        <dynamics>
          <spring_reference>0</spring_reference>
          <spring_stiffness>0</spring_stiffness>
        </dynamics>
        <use_parent_model_frame>1</use_parent_model_frame>
      </axis>
    </joint>
    <link name='summit_xl_rear_laser_base_link'>
      <pose frame=''>-0.2865 0.20894 0.4243 3.14159 0 2.35619</pose>
      <inertial>
        <pose frame=''>0 0 0 0 -0 0</pose>
        <mass>0.1</mass>
        <inertia>
          <ixx>0.000270833</ixx>
          <ixy>0</ixy>
          <ixz>0</ixz>
          <iyy>0.000270833</iyy>
          <iyz>0</iyz>
          <izz>9.434e-05</izz>
        </inertia>
      </inertial>
      <collision name='summit_xl_rear_laser_base_link_collision'>
        <pose frame=''>0 0 0 0 -0 0</pose>
        <geometry>
          <mesh>
            <scale>1 1 1</scale>
            <uri>model://robotnik_sensors/meshes/sick_s300.dae</uri>
          </mesh>
        </geometry>
      </collision>
      <visual name='summit_xl_rear_laser_base_link_visual'>
        <pose frame=''>0 0 0 0 -0 0</pose>
        <geometry>
          <mesh>
            <scale>1 1 1</scale>
            <uri>model://robotnik_sensors/meshes/sick_s300.dae</uri>
          </mesh>
        </geometry>
      </visual>
      <gravity>1</gravity>
      <velocity_decay/>
      <sensor name='summit_xl_rear_laser_sensor' type='ray'>
        <visualize>0</visualize>
        <update_rate>12.5</update_rate>
        <ray>
          <scan>
            <horizontal>
              <samples>541</samples>
              <resolution>1</resolution>
              <min_angle>-2.3562</min_angle>
              <max_angle>2.3562</max_angle>
            </horizontal>
          </scan>
          <range>
            <min>0.1</min>
            <max>30</max>
            <resolution>0.03</resolution>
          </range>
          <noise>
            <type>gaussian</type>
            <mean>0</mean>
            <stddev>0.03</stddev>
          </noise>
        </ray>
        <plugin name='summit_xl_rear_laser_controller' filename='libgazebo_ros_laser.so'>
          <topicName>rear_laser/scan</topicName>
          <frameName>/summit_xl_rear_laser_link</frameName>
        </plugin>
        <pose frame=''>0 0 0.116 0 -0 0</pose>
      </sensor>
    </link>
    <joint name='summit_xl_rear_laser_base_joint' type='revolute'>
      <child>summit_xl_rear_laser_base_link</child>
      <parent>summit_xl_base_footprint</parent>
      <axis>
        <xyz>-0.707107 0.707107 -0</xyz>
        <limit>
          <lower>0</lower>
          <upper>0</upper>
          <effort>100</effort>
          <velocity>100</velocity>
        </limit>
        <dynamics>
          <spring_reference>0</spring_reference>
          <spring_stiffness>0</spring_stiffness>
        </dynamics>
        <use_parent_model_frame>1</use_parent_model_frame>
      </axis>
    </joint>
    <static>0</static>
    <plugin name='ros_control' filename='libgazebo_ros_control.so'>
      <robotParam>robot_description</robotParam>
      <controlPeriod>0.001</controlPeriod>
      <robotSimType>gazebo_ros_control/DefaultRobotHWSim</robotSimType>
      <legacyModeNS>1</legacyModeNS>
    </plugin>
  </model>
</sdf>
