<?xml version="1.0" encoding="utf-8"?>
<!-- =================================================================================== -->
<!-- |    This document was autogenerated by xacro from summit_xls_std.urdf.xacro      | -->
<!-- |    EDITING THIS FILE BY HAND IS NOT RECOMMENDED                                 | -->
<!-- =================================================================================== -->
<robot name="summit_xl">
  <!-- ***************** -->
  <!-- Imported elements -->
  <!-- ***************** -->
  <!-- First we import all posible elements defined in the urdf.xacro files. All these elements are defined as macro:xacros -->
  <gazebo reference="base_footprint">
    <material>Gazebo/Green</material>
  </gazebo>
  <!-- in kg-->
  <!-- in kg-->
  <!-- This file unifies all sensors that can be used on simulation, defined as xacro:macros -->
  <!-- Includes -->
  <gazebo>
    <plugin filename="libgazebo_ros_control.so" name="ros_control">
      <!--<robotNamespace>/summit_xl</robotNamespace>-->
      <robotParam>robot_description</robotParam>
      <controlPeriod>0.001</controlPeriod>
      <robotSimType>gazebo_ros_control/DefaultRobotHWSim</robotSimType>
      <legacyModeNS>true</legacyModeNS>
    </plugin>
  </gazebo>
  <!-- *************** -->
  <!-- Robots Elements -->
  <!-- *************** -->
  <!-- Here we create the robot elements using the xacro:macros imported at the beggining of this file -->
  <link name="summit_xl_base_footprint">
    <visual>
      <origin rpy="0 0 0" xyz="0 0 0"/>
      <geometry>
        <box size="0.001 0.001 0.001"/>
      </geometry>
    </visual>
  </link>
  <joint name="summit_xl_base_footprint_joint" type="fixed">
    <origin rpy="0 0 0" xyz="0 0 0.127"/>
    <!-- ${wheel_radius} property must be defined inside wheel description -->
    <parent link="summit_xl_base_footprint"/>
    <child link="summit_xl_base_link"/>
  </joint>
  <!-- COLLISON -->
  <link name="summit_xl_collision_box">
    <origin rpy="0 0 0" xyz="0 0 0"/>
    <geometry>
      <box size="0.8 0.8 0.8"/>
    </geometry>
    <collision name="summit_xl_collision_box">
      <geometry>
        <box size="0.8 0.8 0.8"/>
      </geometry>
    </collision>
  </link>
  <joint name="box_joint" type="fixed">
    <parent link="summit_xl_base_footprint"/>
    <child link="summit_xl_collision_box"/>
    <origin rpy="0 0 0" xyz="0.0 0.0 0.5"/>
  </joint>
  <!-- BASE_LINK -->
  <link name="summit_xl_base_link">
    <inertial>
      <mass value="125.0"/>
      <origin xyz="0 0 0"/>
      <inertia ixx="1.391" ixy="0.004" ixz="0.0" iyy="6.853" iyz="0.0" izz="6.125"/>
    </inertial>
    <visual>
      <origin rpy="0 0 0" xyz="0 0 0"/>
      <geometry>
        <mesh filename="package://summit_xl_description/meshes/bases/xls/summit_xls_chassis.stl"/>
      </geometry>
      <material name="black">
        <color rgba="0.0 0.0 0.0 1"/>
      </material>
    </visual>
    <collision>
      <origin rpy="0 0 0 " xyz="0 0 0"/>
      <geometry>
        <mesh filename="package://summit_xl_description/meshes/bases/xls/summit_xls_chassis.dae"/>
      </geometry>
    </collision>
  </link>
  <gazebo reference="summit_xl_base_link">
    <material>Gazebo/Black</material>
  </gazebo>
  <!-- CHAPAS INOX TAPAS -->
  <link name="summit_xl_base_chapa">
    <visual>
      <origin rpy="0 0 0" xyz="0 0 0"/>
      <geometry>
        <mesh filename="package://summit_xl_description/meshes/bases/xls/summit_xls_chapas_inox_tapas.stl"/>
      </geometry>
      <material name="darkgrey">
        <color rgba="0.5 0.5 0.5 1"/>
      </material>
    </visual>
  </link>
  <joint name="summit_xl_base_tapa_joint" type="fixed">
    <origin rpy="0 0 0" xyz="0.0 0 0.38062"/>
    <parent link="summit_xl_base_link"/>
    <child link="summit_xl_base_chapa"/>
  </joint>
  <!-- LOGO ROBOTNIK IZQUIERDO -->
  <link name="summit_xl_base_logo_left">
    <visual>
      <origin rpy="0 0 0" xyz="0 0 0"/>
      <geometry>
        <mesh filename="package://summit_xl_description/meshes/bases/xls/robotnik_logo_chasis.stl"/>
      </geometry>
      <material name="darkgrey">
        <color rgba="0.5 0.5 0.5 1"/>
      </material>
    </visual>
  </link>
  <joint name="summit_xl_base_logo_left_joint" type="fixed">
    <origin rpy="0 0 0" xyz="0.0 0.28931 0.29062"/>
    <parent link="summit_xl_base_link"/>
    <child link="summit_xl_base_logo_left"/>
  </joint>
  <!-- LOGO ROBOTNIK DERECHO -->
  <link name="summit_xl_base_logo_right">
    <visual>
      <origin rpy="0 0 0" xyz="0 0 0"/>
      <geometry>
        <mesh filename="package://summit_xl_description/meshes/bases/xls/robotnik_logo_chasis.stl"/>
      </geometry>
      <material name="darkgrey">
        <color rgba="0.5 0.5 0.5 1"/>
      </material>
    </visual>
  </link>
  <joint name="summit_xl_base_logo_right_joint" type="fixed">
    <origin rpy="0 0 3.14159265359" xyz="0.0 -0.28931 0.29062"/>
    <parent link="summit_xl_base_link"/>
    <child link="summit_xl_base_logo_right"/>
  </joint>
  <!-- LOGO ROBOTNIK FRONTAL -->
  <link name="summit_xl_base_logo_front">
    <visual>
      <origin rpy="0 0 0" xyz="0 0 0"/>
      <geometry>
        <mesh filename="package://summit_xl_description/meshes/bases/xls/robotnik_logo_chasis.stl"/>
      </geometry>
      <material name="darkgrey">
        <color rgba="0.5 0.5 0.5 1"/>
      </material>
    </visual>
  </link>
  <joint name="summit_xl_base_logo_front_joint" type="fixed">
    <origin rpy="0 0 -1.57079632679" xyz="0.345 0.0 0.0"/>
    <parent link="summit_xl_base_link"/>
    <child link="summit_xl_base_logo_front"/>
  </joint>
  <!-- LOGO ROBOTNIK TRASERO -->
  <link name="summit_xl_base_logo_rear">
    <visual>
      <origin rpy="0 0 0" xyz="0 0 0"/>
      <geometry>
        <mesh filename="package://summit_xl_description/meshes/bases/xls/robotnik_logo_chasis.stl"/>
      </geometry>
      <material name="darkgrey">
        <color rgba="0.5 0.5 0.5 1"/>
      </material>
    </visual>
  </link>
  <joint name="summit_xl_base_logo_rear_joint" type="fixed">
    <origin rpy="0 0 1.57079632679" xyz="-0.345 0.0 0.0"/>
    <parent link="summit_xl_base_link"/>
    <child link="summit_xl_base_logo_rear"/>
  </joint>
  <!-- DOCKING CONTACT -->
  <link name="summit_xl_base_docking_contact">
    </link>
  <joint name="summit_xl_base_docking_joint" type="fixed">
    <origin rpy="0 0 0" xyz="0.35 0 0.09"/>
    <parent link="summit_xl_base_link"/>
    <child link="summit_xl_base_docking_contact"/>
  </joint>
  <joint name="summit_xl_front_right_wheel_joint" type="continuous">
    <parent link="summit_xl_base_link"/>
    <child link="summit_xl_front_right_wheel_link"/>
    <origin rpy="0 0 0" xyz="0.2225 -0.2045 0.0"/>
    <axis rpy="0 0 0" xyz="0 1 0"/>
    <limit effort="100" velocity="100"/>
    <joint_properties damping="0.0" friction="0.0"/>
  </joint>
  <link name="summit_xl_front_right_wheel_link">
    <visual>
      <origin rpy="0 0 0" xyz="0 0 0"/>
      <geometry>
        <mesh filename="package://summit_xl_description/meshes/wheels/omni_wheel_2.dae"/>
      </geometry>
      <material name="darkgrey">
        <color rgba="0.2 0.2 0.2 1"/>
      </material>
    </visual>
    <collision>
      <origin rpy="1.57079632679 0 0" xyz="0 0 0"/>
      <geometry>
        <!--sphere radius="${omni_wheel_radius}" /-->
        <!--
          <xacro:if value="${reflect}">
              <mesh filename="package://summit_xl_description/meshes/wheels/omni_wheel_1.dae" />
          </xacro:if>
          <xacro:unless value="${reflect}">
              <mesh filename="package://summit_xl_description/meshes/wheels/omni_wheel_2.dae" />
					</xacro:unless>
-->
        <cylinder length="0.087" radius="0.127"/>
      </geometry>
    </collision>
    <inertial>
      <mass value="6.5"/>
      <origin xyz="0 0 0"/>
      <inertia ixx="0.0303095" ixy="0" ixz="0" iyy="0.05241925" iyz="0" izz="0.0303095"/>
    </inertial>
  </link>
  <!-- Transmission is important to link the joints and the controller (see summit_xl_control/config/summit_xl_control.yaml)-->
  <transmission name="summit_xl_front_right_wheel_joint_trans">
    <type>transmission_interface/SimpleTransmission</type>
    <joint name="summit_xl_front_right_wheel_joint">
      <hardwareInterface>hardware_interface/VelocityJointInterface</hardwareInterface>
    </joint>
    <actuator name="summit_xl_front_right_wheel_joint_motor">
      <mechanicalReduction>1</mechanicalReduction>
    </actuator>
  </transmission>
  <gazebo reference="summit_xl_front_right_wheel_link">
    <mu1 value="0.0"/>
    <mu2 value="0.0"/>
    <kp value="10000000.0"/>
    <kd value="1.0"/>
    <fdir1 value="1 0 0"/>
    <turnGravityOff>false</turnGravityOff>
  </gazebo>
  <joint name="summit_xl_front_left_wheel_joint" type="continuous">
    <parent link="summit_xl_base_link"/>
    <child link="summit_xl_front_left_wheel_link"/>
    <origin rpy="0 0 0" xyz="0.2225 0.2045 0.0"/>
    <axis rpy="0 0 0" xyz="0 1 0"/>
    <limit effort="100" velocity="100"/>
    <joint_properties damping="0.0" friction="0.0"/>
  </joint>
  <link name="summit_xl_front_left_wheel_link">
    <visual>
      <origin rpy="0 0 0" xyz="0 0 0"/>
      <geometry>
        <mesh filename="package://summit_xl_description/meshes/wheels/omni_wheel_1.dae"/>
      </geometry>
      <material name="darkgrey">
        <color rgba="0.2 0.2 0.2 1"/>
      </material>
    </visual>
    <collision>
      <origin rpy="1.57079632679 0 0" xyz="0 0 0"/>
      <geometry>
        <!--sphere radius="${omni_wheel_radius}" /-->
        <!--
          <xacro:if value="${reflect}">
              <mesh filename="package://summit_xl_description/meshes/wheels/omni_wheel_1.dae" />
          </xacro:if>
          <xacro:unless value="${reflect}">
              <mesh filename="package://summit_xl_description/meshes/wheels/omni_wheel_2.dae" />
					</xacro:unless>
-->
        <cylinder length="0.087" radius="0.127"/>
      </geometry>
    </collision>
    <inertial>
      <mass value="6.5"/>
      <origin xyz="0 0 0"/>
      <inertia ixx="0.0303095" ixy="0" ixz="0" iyy="0.05241925" iyz="0" izz="0.0303095"/>
    </inertial>
  </link>
  <!-- Transmission is important to link the joints and the controller (see summit_xl_control/config/summit_xl_control.yaml)-->
  <transmission name="summit_xl_front_left_wheel_joint_trans">
    <type>transmission_interface/SimpleTransmission</type>
    <joint name="summit_xl_front_left_wheel_joint">
      <hardwareInterface>hardware_interface/VelocityJointInterface</hardwareInterface>
    </joint>
    <actuator name="summit_xl_front_left_wheel_joint_motor">
      <mechanicalReduction>1</mechanicalReduction>
    </actuator>
  </transmission>
  <gazebo reference="summit_xl_front_left_wheel_link">
    <mu1 value="0.0"/>
    <mu2 value="0.0"/>
    <kp value="10000000.0"/>
    <kd value="1.0"/>
    <fdir1 value="1 0 0"/>
    <turnGravityOff>false</turnGravityOff>
  </gazebo>
  <joint name="summit_xl_back_left_wheel_joint" type="continuous">
    <parent link="summit_xl_base_link"/>
    <child link="summit_xl_back_left_wheel_link"/>
    <origin rpy="0 0 0" xyz="-0.2225 0.2045 0.0"/>
    <axis rpy="0 0 0" xyz="0 1 0"/>
    <limit effort="100" velocity="100"/>
    <joint_properties damping="0.0" friction="0.0"/>
  </joint>
  <link name="summit_xl_back_left_wheel_link">
    <visual>
      <origin rpy="0 0 0" xyz="0 0 0"/>
      <geometry>
        <mesh filename="package://summit_xl_description/meshes/wheels/omni_wheel_1.dae"/>
      </geometry>
      <material name="darkgrey">
        <color rgba="0.2 0.2 0.2 1"/>
      </material>
    </visual>
    <collision>
      <origin rpy="1.57079632679 0 0" xyz="0 0 0"/>
      <geometry>
        <!--sphere radius="${omni_wheel_radius}" /-->
        <!--
          <xacro:if value="${reflect}">
              <mesh filename="package://summit_xl_description/meshes/wheels/omni_wheel_1.dae" />
          </xacro:if>
          <xacro:unless value="${reflect}">
              <mesh filename="package://summit_xl_description/meshes/wheels/omni_wheel_2.dae" />
					</xacro:unless>
-->
        <cylinder length="0.087" radius="0.127"/>
      </geometry>
    </collision>
    <inertial>
      <mass value="6.5"/>
      <origin xyz="0 0 0"/>
      <inertia ixx="0.0303095" ixy="0" ixz="0" iyy="0.05241925" iyz="0" izz="0.0303095"/>
    </inertial>
  </link>
  <!-- Transmission is important to link the joints and the controller (see summit_xl_control/config/summit_xl_control.yaml)-->
  <transmission name="summit_xl_back_left_wheel_joint_trans">
    <type>transmission_interface/SimpleTransmission</type>
    <joint name="summit_xl_back_left_wheel_joint">
      <hardwareInterface>hardware_interface/VelocityJointInterface</hardwareInterface>
    </joint>
    <actuator name="summit_xl_back_left_wheel_joint_motor">
      <mechanicalReduction>1</mechanicalReduction>
    </actuator>
  </transmission>
  <gazebo reference="summit_xl_back_left_wheel_link">
    <mu1 value="0.0"/>
    <mu2 value="0.0"/>
    <kp value="10000000.0"/>
    <kd value="1.0"/>
    <fdir1 value="1 0 0"/>
    <turnGravityOff>false</turnGravityOff>
  </gazebo>
  <joint name="summit_xl_back_right_wheel_joint" type="continuous">
    <parent link="summit_xl_base_link"/>
    <child link="summit_xl_back_right_wheel_link"/>
    <origin rpy="0 0 0" xyz="-0.2225 -0.2045 0.0"/>
    <axis rpy="0 0 0" xyz="0 1 0"/>
    <limit effort="100" velocity="100"/>
    <joint_properties damping="0.0" friction="0.0"/>
  </joint>
  <link name="summit_xl_back_right_wheel_link">
    <visual>
      <origin rpy="0 0 0" xyz="0 0 0"/>
      <geometry>
        <mesh filename="package://summit_xl_description/meshes/wheels/omni_wheel_2.dae"/>
      </geometry>
      <material name="darkgrey">
        <color rgba="0.2 0.2 0.2 1"/>
      </material>
    </visual>
    <collision>
      <origin rpy="1.57079632679 0 0" xyz="0 0 0"/>
      <geometry>
        <!--sphere radius="${omni_wheel_radius}" /-->
        <!--
          <xacro:if value="${reflect}">
              <mesh filename="package://summit_xl_description/meshes/wheels/omni_wheel_1.dae" />
          </xacro:if>
          <xacro:unless value="${reflect}">
              <mesh filename="package://summit_xl_description/meshes/wheels/omni_wheel_2.dae" />
					</xacro:unless>
-->
        <cylinder length="0.087" radius="0.127"/>
      </geometry>
    </collision>
    <inertial>
      <mass value="6.5"/>
      <origin xyz="0 0 0"/>
      <inertia ixx="0.0303095" ixy="0" ixz="0" iyy="0.05241925" iyz="0" izz="0.0303095"/>
    </inertial>
  </link>
  <!-- Transmission is important to link the joints and the controller (see summit_xl_control/config/summit_xl_control.yaml)-->
  <transmission name="summit_xl_back_right_wheel_joint_trans">
    <type>transmission_interface/SimpleTransmission</type>
    <joint name="summit_xl_back_right_wheel_joint">
      <hardwareInterface>hardware_interface/VelocityJointInterface</hardwareInterface>
    </joint>
    <actuator name="summit_xl_back_right_wheel_joint_motor">
      <mechanicalReduction>1</mechanicalReduction>
    </actuator>
  </transmission>
  <gazebo reference="summit_xl_back_right_wheel_link">
    <mu1 value="0.0"/>
    <mu2 value="0.0"/>
    <kp value="10000000.0"/>
    <kd value="1.0"/>
    <fdir1 value="1 0 0"/>
    <turnGravityOff>false</turnGravityOff>
  </gazebo>
  <joint name="summit_xl_imu_joint" type="fixed">
    <axis xyz="1 0 0"/>
    <!--origin xyz="0 0 0.2825"/-->
    <origin rpy="0 0 0" xyz="0.127 -0.129 0.212"/>
    <parent link="summit_xl_base_link"/>
    <child link="summit_xl_imu_link"/>
  </joint>
  <link name="summit_xl_imu_link">
    <inertial>
      <mass value="0.001"/>
      <origin rpy="0 0 0" xyz="0 0 0"/>
      <inertia ixx="0.00000000167" ixy="0" ixz="0" iyy="0.00000000167" iyz="0" izz="0.00000000167"/>
    </inertial>
    <visual>
      <origin rpy="0 0 0" xyz="0 0 0"/>
      <geometry>
        <box size="0.001 0.001 0.001"/>
      </geometry>
    </visual>
    <!--collision>
	        <origin rpy="0 0 0" xyz="0 0 0"/>
	        <geometry>
	          <box size=".001 .001 .001"/>
	        </geometry>
	      </collision-->
  </link>
  <!--<gazebo>-->
  <!--<plugin name="${prefix}_controller" filename="libgazebo_ros_imu.so">-->
  <!--<topicName>${ns}imu/data</topicName>-->
  <!--<serviceName>imu/service</serviceName>-->
  <!--<bodyName>${prefix}_link</bodyName>-->
  <!--<updateRateHZ>50.0</updateRateHZ>-->
  <!--<gaussianNoise>0.0</gaussianNoise>-->
  <!--</plugin>-->
  <!--</gazebo>-->
  <gazebo reference="summit_xl_imu_link">
    <gravity>true</gravity>
    <sensor name="summit_xl_imu_imu_sensor" type="imu">
      <always_on>true</always_on>
      <update_rate>100</update_rate>
      <visualize>true</visualize>
      <topic>__default_topic__</topic>
      <plugin filename="libgazebo_ros_imu_sensor.so" name="summit_xl_imu_imu_plugin">
        <topicName>imu/data</topicName>
        <bodyName>summit_xl_imu_link</bodyName>
        <updateRateHZ>100.0</updateRateHZ>
        <gaussianNoise>0.0</gaussianNoise>
        <xyzOffset>0 0 0</xyzOffset>
        <rpyOffset>0 0 0</rpyOffset>
        <frameName>summit_xl_imu_link</frameName>
      </plugin>
      <pose>0 0 0 0 0 0</pose>
    </sensor>
  </gazebo>
  <joint name="summit_xl_front_laser_base_joint" type="revolute">
    <origin rpy="0 -3.14159265359 2.35619449019" xyz="0.2865 -0.20894 0.2973"/>
    <parent link="summit_xl_base_link"/>
    <child link="summit_xl_front_laser_base_link"/>
    <limit effort="100" lower="0.0" upper="0.0" velocity="100"/>
  </joint>
  <link name="summit_xl_front_laser_base_link">
    <collision>
      <origin rpy="0 0 0" xyz="0 0 0"/>
      <geometry>
        <!--<box size="0.106 0.094 0.152"/>-->
        <!--<cylinder radius="0.058" length="0.152"/>-->
        <mesh filename="package://robotnik_sensors/meshes/sick_s300.dae"/>
      </geometry>
    </collision>
    <visual>
      <origin rpy="0 0 0" xyz="0 0 0"/>
      <geometry>
        <mesh filename="package://robotnik_sensors/meshes/sick_s300.dae"/>
      </geometry>
    </visual>
    <!--inertial>
			<mass value="1e-5" />
			<origin xyz="0 0 0" rpy="0 0 0"/>
			<inertia ixx="1e-6" ixy="0" ixz="0" iyy="1e-6" iyz="0" izz="1e-6" />
		</inertial-->
    <inertial>
      <mass value="0.1"/>
      <origin rpy="0 0 0" xyz="0 0 0"/>
      <inertia ixx="0.0002708333" ixy="0" ixz="0" iyy="0.0002708333" iyz="0" izz="0.00009434"/>
    </inertial>
  </link>
  <joint name="summit_xl_front_laser_joint" type="fixed">
    <parent link="summit_xl_front_laser_base_link"/>
    <child link="summit_xl_front_laser_link"/>
    <origin rpy="0 0 0" xyz="0.0 0 0.116"/>
  </joint>
  <link name="summit_xl_front_laser_link"/>
  <transmission name="summit_xl_front_laser_base_trans">
    <type>transmission_interface/SimpleTransmission</type>
    <joint name="summit_xl_front_laser_base_joint">
      <hardwareInterface>hardware_interface/VelocityJointInterface</hardwareInterface>
    </joint>
    <actuator name="sick_motor">
      <hardwareInterface>hardware_interface/VelocityJointInterface</hardwareInterface>
      <mechanicalReduction>1.0</mechanicalReduction>
    </actuator>
  </transmission>
  <gazebo reference="summit_xl_front_laser_link">
    <sensor name="summit_xl_front_laser_sensor" type="ray">
      <pose>0 0 0 0 0 0</pose>
      <visualize>false</visualize>
      <update_rate>12.5</update_rate>
      <ray>
        <scan>
          <horizontal>
            <samples>541</samples>
            <resolution>1</resolution>
            <min_angle>-2.3562</min_angle>
            <max_angle>2.3562</max_angle>
          </horizontal>
        </scan>
        <range>
          <min>0.10</min>
          <max>30.0</max>
          <resolution>0.03</resolution>
        </range>
        <noise>
          <type>gaussian</type>
          <mean>0.0</mean>
          <stddev>0.03</stddev>
        </noise>
      </ray>
      <plugin filename="libgazebo_ros_laser.so" name="summit_xl_front_laser_controller">
        <topicName>front_laser/scan</topicName>
        <frameName>/summit_xl_front_laser_link</frameName>
        <!-- if not global (leading /) sets the current namespace as a prefix (/ns/name_laser_link) -->
      </plugin>
    </sensor>
  </gazebo>
  <joint name="summit_xl_rear_laser_base_joint" type="revolute">
    <origin rpy="0 -3.14159265359 -0.785398163397" xyz="-0.2865 0.20894 0.2973"/>
    <parent link="summit_xl_base_link"/>
    <child link="summit_xl_rear_laser_base_link"/>
    <limit effort="100" lower="0.0" upper="0.0" velocity="100"/>
  </joint>
  <link name="summit_xl_rear_laser_base_link">
    <collision>
      <origin rpy="0 0 0" xyz="0 0 0"/>
      <geometry>
        <!--<box size="0.106 0.094 0.152"/>-->
        <!--<cylinder radius="0.058" length="0.152"/>-->
        <mesh filename="package://robotnik_sensors/meshes/sick_s300.dae"/>
      </geometry>
    </collision>
    <visual>
      <origin rpy="0 0 0" xyz="0 0 0"/>
      <geometry>
        <mesh filename="package://robotnik_sensors/meshes/sick_s300.dae"/>
      </geometry>
    </visual>
    <!--inertial>
			<mass value="1e-5" />
			<origin xyz="0 0 0" rpy="0 0 0"/>
			<inertia ixx="1e-6" ixy="0" ixz="0" iyy="1e-6" iyz="0" izz="1e-6" />
		</inertial-->
    <inertial>
      <mass value="0.1"/>
      <origin rpy="0 0 0" xyz="0 0 0"/>
      <inertia ixx="0.0002708333" ixy="0" ixz="0" iyy="0.0002708333" iyz="0" izz="0.00009434"/>
    </inertial>
  </link>
  <joint name="summit_xl_rear_laser_joint" type="fixed">
    <parent link="summit_xl_rear_laser_base_link"/>
    <child link="summit_xl_rear_laser_link"/>
    <origin rpy="0 0 0" xyz="0.0 0 0.116"/>
  </joint>
  <link name="summit_xl_rear_laser_link"/>
  <transmission name="summit_xl_rear_laser_base_trans">
    <type>transmission_interface/SimpleTransmission</type>
    <joint name="summit_xl_rear_laser_base_joint">
      <hardwareInterface>hardware_interface/VelocityJointInterface</hardwareInterface>
    </joint>
    <actuator name="sick_motor">
      <hardwareInterface>hardware_interface/VelocityJointInterface</hardwareInterface>
      <mechanicalReduction>1.0</mechanicalReduction>
    </actuator>
  </transmission>
  <gazebo reference="summit_xl_rear_laser_link">
    <sensor name="summit_xl_rear_laser_sensor" type="ray">
      <pose>0 0 0 0 0 0</pose>
      <visualize>false</visualize>
      <update_rate>12.5</update_rate>
      <ray>
        <scan>
          <horizontal>
            <samples>541</samples>
            <resolution>1</resolution>
            <min_angle>-2.3562</min_angle>
            <max_angle>2.3562</max_angle>
          </horizontal>
        </scan>
        <range>
          <min>0.10</min>
          <max>30.0</max>
          <resolution>0.03</resolution>
        </range>
        <noise>
          <type>gaussian</type>
          <mean>0.0</mean>
          <stddev>0.03</stddev>
        </noise>
      </ray>
      <plugin filename="libgazebo_ros_laser.so" name="summit_xl_rear_laser_controller">
        <topicName>rear_laser/scan</topicName>
        <frameName>/summit_xl_rear_laser_link</frameName>
        <!-- if not global (leading /) sets the current namespace as a prefix (/ns/name_laser_link) -->
      </plugin>
    </sensor>
  </gazebo>
  <!--xacro:sensor_axis_m5013 prefix="$(arg prefix)front_ptz_camera" parent="$(arg prefix)base_link">
			<origin xyz="${front_ptz_camera_offset_x} ${front_ptz_camera_offset_y} ${front_ptz_camera_offset_z}" rpy="${-PI/2} 0 0"/>
		</xacro:sensor_axis_m5013-->
  <!--xacro:sensor_axis_m5013 prefix="$(arg prefix)rear_ptz_camera" parent="$(arg prefix)base_link">
			<origin xyz="${rear_ptz_camera_offset_x} ${rear_ptz_camera_offset_y} ${rear_ptz_camera_offset_z}" rpy="${-PI/2} 0 ${PI}"/>
		</xacro:sensor_axis_m5013-->
  <joint name="summit_xl_front_rgbd_camera_rgb_joint" type="fixed">
    <origin rpy="0 0 0" xyz="0.3585 0.0 0.25062"/>
    <parent link="summit_xl_base_link"/>
    <child link="summit_xl_front_rgbd_camera_rgb_base_link"/>
  </joint>
  <link name="summit_xl_front_rgbd_camera_rgb_base_link">
    <inertial>
      <mass value="0.001"/>
      <origin xyz="0 0 0"/>
      <inertia ixx="0.0001" ixy="0.0" ixz="0.0" iyy="0.0001" iyz="0.0" izz="0.0001"/>
    </inertial>
  </link>
  <joint name="summit_xl_front_rgbd_camera_rgb_optical_joint" type="fixed">
    <origin rpy="-1.57079632679 0 -1.57079632679" xyz="0.0 0.0 0.0"/>
    <parent link="summit_xl_front_rgbd_camera_rgb_base_link"/>
    <child link="summit_xl_front_rgbd_camera_rgb_optical_frame"/>
  </joint>
  <link name="summit_xl_front_rgbd_camera_rgb_optical_frame">
    <!--inertial>
        <mass value="0.001" />
        <origin xyz="0 0 0" />
        <inertia ixx="0.0001" ixy="0.0" ixz="0.0"
          iyy="0.0001" iyz="0.0"
          izz="0.0001" />
      </inertial-->
  </link>
  <joint name="summit_xl_front_rgbd_camera_joint" type="fixed">
    <origin rpy="0.0 0 0" xyz="0.0 -0.0125 -0.015"/>
    <parent link="summit_xl_front_rgbd_camera_rgb_base_link"/>
    <child link="summit_xl_front_rgbd_camera_link"/>
  </joint>
  <link name="summit_xl_front_rgbd_camera_link">
    <visual>
      <origin rpy="0 0 0" xyz="0 0 0"/>
      <geometry>
        <mesh filename="package://robotnik_sensors/meshes/orbbec_astra.dae" scale="1.0 1.0 1.0"/>
      </geometry>
    </visual>
    <collision>
      <origin rpy="0 0 0" xyz="0.0 0.0 0.0"/>
      <!--geometry>
        <box size="0.0730 .2760 0.0720"/>
      </geometry-->
      <geometry>
        <mesh filename="package://robotnik_sensors/meshes/orbbec_astra.dae" scale="1.0 1.0 1.0"/>
      </geometry>
    </collision>
    <inertial>
      <!--mass value="0.01" />
        <origin xyz="0 0 0" />
        <inertia ixx="0.001" ixy="0.0" ixz="0.0"
          iyy="0.001" iyz="0.0"
          izz="0.001" /-->
      <mass value="0.564"/>
      <origin xyz="0 0 0"/>
      <inertia ixx="0.003881243" ixy="0.0" ixz="0.0" iyy="0.000498940" iyz="0.0" izz="0.003879257"/>
    </inertial>
  </link>
  <joint name="summit_xl_front_rgbd_camera_depth_joint" type="fixed">
    <origin rpy="0 0 0" xyz="0.0 0.025 0.0"/>
    <parent link="summit_xl_front_rgbd_camera_rgb_base_link"/>
    <child link="summit_xl_front_rgbd_camera_depth_frame"/>
  </joint>
  <link name="summit_xl_front_rgbd_camera_depth_frame">
    <!--inertial>
        <mass value="0.01" />
        <origin xyz="0 0 0" />
        <inertia ixx="0.001" ixy="0.0" ixz="0.0"
          iyy="0.001" iyz="0.0"
          izz="0.001" />
      </inertial-->
  </link>
  <joint name="summit_xl_front_rgbd_camera_depth_optical_joint" type="fixed">
    <origin rpy="-1.57079632679 0 -1.57079632679" xyz="0 0 0"/>
    <parent link="summit_xl_front_rgbd_camera_depth_frame"/>
    <child link="summit_xl_front_rgbd_camera_depth_optical_frame"/>
  </joint>
  <link name="summit_xl_front_rgbd_camera_depth_optical_frame">
    <!--inertial>
        <mass value="0.001" />
        <origin xyz="0 0 0" />
        <inertia ixx="0.0001" ixy="0.0" ixz="0.0"
          iyy="0.0001" iyz="0.0"
          izz="0.0001" />
      </inertial-->
  </link>
  <gazebo reference="summit_xl_front_rgbd_camera_rgb_base_link">
    <sensor name="summit_xl_front_rgbd_camera_depth_sensor" type="depth">
      <always_on>true</always_on>
      <update_rate>20.0</update_rate>
      <camera>
        <horizontal_fov>1.0471975512</horizontal_fov>
        <image>
          <format>R8G8B8</format>
          <width>640</width>
          <height>480</height>
        </image>
        <clip>
          <near>0.05</near>
          <far>3.5</far>
        </clip>
      </camera>
      <plugin filename="libgazebo_ros_openni_kinect.so" name="summit_xl_front_rgbd_camera_controller">
        <cameraName>front_rgbd_camera</cameraName>
        <alwaysOn>true</alwaysOn>
        <updateRate>10</updateRate>
        <imageTopicName>rgb/image_raw</imageTopicName>
        <depthImageTopicName>depth/image_raw</depthImageTopicName>
        <pointCloudTopicName>depth/points</pointCloudTopicName>
        <cameraInfoTopicName>rgb/camera_info</cameraInfoTopicName>
        <depthImageCameraInfoTopicName>depth/camera_info</depthImageCameraInfoTopicName>
        <frameName>/summit_xl_front_rgbd_camera_depth_optical_frame</frameName>
        <baseline>0.1</baseline>
        <distortion_k1>0.0</distortion_k1>
        <distortion_k2>0.0</distortion_k2>
        <distortion_k3>0.0</distortion_k3>
        <distortion_t1>0.0</distortion_t1>
        <distortion_t2>0.0</distortion_t2>
        <pointCloudCutoff>0.4</pointCloudCutoff>
      </plugin>
    </sensor>
  </gazebo>
  <!--xacro:sensor_gps prefix="$(arg prefix)gps" parent="$(arg prefix)base_link">
			<origin xyz="${gps_offset_x} ${gps_offset_y} ${gps_offset_z}" rpy="0 0 0"/>
		</xacro:sensor_gps-->
  <gazebo reference="summit_xl_base_link">
    <sensor name="body_contact" type="contact">
      <contact>
        <!--<collision>robot::robot_base_footprint::robot_base_footprint_fixed_joint_lump__robot_base_link_collision</collision>-->
        <collision>robot::robot_base_footprint::robot_base_footprint_fixed_joint_lump__robot_collision_box_collision</collision>
        <topic>__default_topic__</topic>
      </contact>
      <plugin filename="libgazebo_ros_bumper.so" name="body_plugin">
        <alwaysOn>true</alwaysOn>
        <bumperTopicName>body_contact</bumperTopicName>
        <frameName>summit_xl_base_footprint</frameName>
      </plugin>
    </sensor>
  </gazebo>
</robot>

